Traceback (most recent call last):
  File "/opt/hostedtoolcache/Python/3.8.12/x64/lib/python3.8/site-packages/jupyter_cache/executors/utils.py", line 51, in single_nb_execution
    executenb(
  File "/opt/hostedtoolcache/Python/3.8.12/x64/lib/python3.8/site-packages/nbclient/client.py", line 1093, in execute
    return NotebookClient(nb=nb, resources=resources, km=km, **kwargs).execute()
  File "/opt/hostedtoolcache/Python/3.8.12/x64/lib/python3.8/site-packages/nbclient/util.py", line 84, in wrapped
    return just_run(coro(*args, **kwargs))
  File "/opt/hostedtoolcache/Python/3.8.12/x64/lib/python3.8/site-packages/nbclient/util.py", line 62, in just_run
    return loop.run_until_complete(coro)
  File "/opt/hostedtoolcache/Python/3.8.12/x64/lib/python3.8/asyncio/base_events.py", line 616, in run_until_complete
    return future.result()
  File "/opt/hostedtoolcache/Python/3.8.12/x64/lib/python3.8/site-packages/nbclient/client.py", line 559, in async_execute
    await self.async_execute_cell(
  File "/opt/hostedtoolcache/Python/3.8.12/x64/lib/python3.8/site-packages/nbclient/client.py", line 854, in async_execute_cell
    self._check_raise_for_error(cell, exec_reply)
  File "/opt/hostedtoolcache/Python/3.8.12/x64/lib/python3.8/site-packages/nbclient/client.py", line 756, in _check_raise_for_error
    raise CellExecutionError.from_cell_and_msg(cell, exec_reply_content)
nbclient.exceptions.CellExecutionError: An error occurred while executing the following cell:
------------------
data = "Hello World!"
data_bytes = data.encode("utf-8")
data_decoded = data_bytes.decode("utf-8")
data_hashed = hashlib.sha256(data_bytes).hexdigest()
print(f"Original: {data}")
print(f" Encoded: {data_bytes}")
print(f" Decoded: {data_decoded}")
print(f"  Hashed: {data_hashed}")
------------------

[0;31m---------------------------------------------------------------------------[0m
[0;31mNameError[0m                                 Traceback (most recent call last)
[0;32m/tmp/ipykernel_2274/2909934302.py[0m in [0;36m<module>[0;34m[0m
[1;32m      2[0m [0mdata_bytes[0m [0;34m=[0m [0mdata[0m[0;34m.[0m[0mencode[0m[0;34m([0m[0;34m"utf-8"[0m[0;34m)[0m[0;34m[0m[0;34m[0m[0m
[1;32m      3[0m [0mdata_decoded[0m [0;34m=[0m [0mdata_bytes[0m[0;34m.[0m[0mdecode[0m[0;34m([0m[0;34m"utf-8"[0m[0;34m)[0m[0;34m[0m[0;34m[0m[0m
[0;32m----> 4[0;31m [0mdata_hashed[0m [0;34m=[0m [0mhashlib[0m[0;34m.[0m[0msha256[0m[0;34m([0m[0mdata_bytes[0m[0;34m)[0m[0;34m.[0m[0mhexdigest[0m[0;34m([0m[0;34m)[0m[0;34m[0m[0;34m[0m[0m
[0m[1;32m      5[0m [0mprint[0m[0;34m([0m[0;34mf"Original: {data}"[0m[0;34m)[0m[0;34m[0m[0;34m[0m[0m
[1;32m      6[0m [0mprint[0m[0;34m([0m[0;34mf" Encoded: {data_bytes}"[0m[0;34m)[0m[0;34m[0m[0;34m[0m[0m

[0;31mNameError[0m: name 'hashlib' is not defined
NameError: name 'hashlib' is not defined

